Workbook

Sheet Leads B2B
A1: NetWiz Systems | Base de dados de prospeção P1 - Leads B2B (Portugal e Espanha)
A2: 166 entidades (80 Portugal + 86 Espanha) em 8 setores prioritários da A4; inclui a base A3 - fontes públicas; nomes oficiais confirmados via web (jul/2026)
A3: Como ler: 4 folhas -> Leads B2B (esta) · Análise (conclusões) · Metodologia (critérios e RGPD) · Glossário (siglas). Prioridade (cor na coluna L): Alta = abordar primeiro · Média = seguir · Baixa = oportunista. Colunas J-K (necessidade/motivo): sinais públicos verificados + inferências de processos internos a validar; a Prioridade (L) é uma recomendação. O serviço NetWiz adequado é atribuído na Tarefa P2 (scorecard).
A4: N.º | B4: País | C4: Empresa / Entidade | D4: Cidade | E4: Setor | F4: Dimensão | G4: Website | H4: Email | I4: Contacto público | J4: Redes sociais | K4: Oportunidade identificada (necessidade digital) | L4: Motivo de interesse | M4: Prioridade | N4: Origem / Estado do dado | O4: Observações
A5: 1 | B5: Portugal | C5: EPET - Escola Profissional de Estudos Técnicos | D5: Lisboa | E5: Educação, ensino profissional e formação | F5: Média | G5: epet.pt | H5: epet@epet.pt | I5: +351 217 609 287 | J5: LinkedIn: https://www.linkedin.com/company/epet---escola-profissional-de-estudos-técnicos/ · Presença institucional pouca ativa | K5: Já tem Moodle, portal do aluno e inscrição online; lacunas menores de otimização e comunicação. | L5: Escola do Grupo Ensinus, digitalmente madura; oportunidade sobretudo de SEO, conversão e comunicação, não de raiz. | M5: Média | N5: Confirmado - verificação web (Exa, jul/2026) | O5: Justificação confirmada e atualizada ao site real.
A6: 2 | B6: Portugal | C6: Escola do Saber | D6: Leiria | E6: Educação, ensino profissional e formação | F6: Pequena | G6: escoladosaber.pt | H6: apoio@escoladosaber.pt | I6: +351 244 097 542 | J6: LinkedIn: https://www.linkedin.com/company/escola-do-saber---formação-profissional/ | K6: Site claramente desatualizado, sem área de formandos nem qualquer componente interativa. | L6: Pequena escola cuja imagem online não reflete a oferta formativa; um redesenho e um portal do formador teriam impacto imediato. | M6: Alta | N6: Confirmado - verificação web (Exa, jul/2026) | O6: Verificado: descrição confere com o site.
A7: 3 | B7: Portugal | C7: EPDRG - Escola Profissional de Desenvolvimento Rural de Grândola | D7: Grândola | E7: Educação, ensino profissional e formação | F7: Pequena | G7: epdrgrandola.pt | H7: direpdrg@gmail.com | I7: +351 269 441 222 | J7: Sem pagina de empresa no LinkedIn | K7: Site atual (notícias 2026) e oferta formativa estruturada; falta portal do aluno/área reservada. | L7: Presença web razoável; oportunidade num portal do aluno e na automatização de candidaturas. | M7: Média | N7: Confirmado - verificação web (Exa, jul/2026) | O7: Nome oficial: Nome oficial no site é "...de Desenvolvimento Rural de Grândola". | Justificação confirmada e atualizada ao site real.
A8: 4 | B8: Portugal | C8: FEPS - Fundação Escola Profissional de Setúbal | D8: Setúbal | E8: Educação, ensino profissional e formação | F8: Média | G8: eps.pt | H8: secretaria@eps.pt | I8: +351 265 729 900 | J8: LinkedIn: https://www.linkedin.com/company/escolaprofissionaldesetubal/ · Redes pouco dinamizadas | K8: O site e básico e sem interatividade, não havendo portal de aluno nem área de parceiros. | L8: Fundação com dimensao para justificar portais dedicados a alunos e a empresas parceiras. | M8: Alta | N8: Confirmado - verificação web (Exa, jul/2026) | O8: Verificado: descrição confere com o site. LinkedIn de empresa confirmado por pesquisa (Exa, jul/2026).
A9: 5 | B9: Portugal | C9: CENFIC / CICCOPN - Academia Lisboa | D9: Loures | E9: Educação, ensino profissional e formação | F9: Grande | G9: cenfic.pt | H9: cenfic@cenfic.pt | I9: +351 219 406 300 | J9: LinkedIn: https://www.linkedin.com/company/cenficcfp/ · Presença digital dispersa | K9: Já tem plataforma de e-learning (LMS) própria e marcações online; lacunas de UX e comunicação. | L9: Centro com LMS ativo; oportunidade de redesenho de UX/UI e reforço de comunicação, não de LMS de raiz. | M9: Média | N9: Confirmado - verificação web (Exa, jul/2026) | O9: Nome oficial: O domínio remete agora para CICCOPN - Academia Lisboa (tem LMS próprio). | Justificação confirmada e atualizada ao site real.
A10: 6 | B10: Portugal | C10: CEAC Corporate - Formação Online | D10: Lisboa | E10: Educação, ensino profissional e formação | F10: Média | G10: ceac-corporate.pt | H10: info@ceac.pt | I10: Formulario no site | J10: Comunicação pouco segmentada | K10: Interface antiquada e percursos de conversao demasiado longos para quem procura formação online. | L10: Opera em ensino a distância, onde a taxa de conversao do site e critica; há ganho claro em rebranding e otimização de campanhas. | M10: Média | N10: Confirmado - verificação web (Exa, jul/2026) | O10: Nome oficial: Marca oficial no site: CEAC Corporate.
A11: 7 | B11: Portugal | C11: Escola Profissional de Torres Vedras | D11: Torres Vedras | E11: Educação, ensino profissional e formação | F11: Pequena | G11: Via CM Torres Vedras | H11: geral@eptv.pt | I11: Site municipal | J11: Sem canais próprios | K11: Depende inteiramente do portal da autarquia, sem domínio nem site próprio. | L11: Escola sem identidade digital autonoma; comeca praticamente do zero, o que a torna uma oportunidade completa. | M11: Média | N11: Validado por análise - fonte pública (justificação estrutural), jul/2026
A12: 8 | B12: Portugal | C12: Escola Profissional de Braga (EPB) | D12: Braga | E12: Educação, ensino profissional e formação | F12: Média | G12: epb.pt | H12: epb@epb.pt | I12: +351 253 254 540 | J12: LinkedIn: https://www.linkedin.com/company/epb-escola-profissional-de-braga/ · Redes com pouca atividade | K12: Escola digitalmente avançada (Microsoft Showcase School); pré-inscrição online, portal de ex-alunos e bolsa de emprego. | L12: Maturidade digital alta; oportunidade pontual de otimização e comunicação. | M12: Baixa | N12: Confirmado - verificação web (Exa, jul/2026) | O12: Justificação confirmada e atualizada ao site real.
A13: 9 | B13: Portugal | C13: Insignare - EPO Escola Profissional de Ourém | D13: Ourém | E13: Educação, ensino profissional e formação | F13: Pequena | G13: insignare.pt | H13: epo@insignare.pt | I13: +351 249 540 390 | J13: LinkedIn: https://www.linkedin.com/company/insignare---associação-de-ensino-e-formação/ | K13: Site com baixa frequência de atualização e ausência de presença profissional nas redes. | L13: Escola local que ganharia visibilidade junto de empregadores com um LinkedIn ativo e captação de leads mais organizada. | M13: Média | N13: Confirmado - verificação web (Exa, jul/2026) | O13: Contacto corrigido (o anterior era inválido). insignare.pt gere a EPO e a Escola de Hotelaria de Fátima.
A14: 10 | B14: Portugal | C14: EPRAL - Escola Profissional da Região Alentejo | D14: Portalegre | E14: Educação, ensino profissional e formação | F14: Pequena | G14: epral.pt | H14: geral@epral.pt | I14: +351 245 339 190 | J14: LinkedIn: https://www.linkedin.com/company/escola-profissional-da-região-alentejo/ · Redes pouco presentes | K14: Site atual (2026) com oferta formativa estruturada; falta portal de candidatura/área do aluno. | L14: Presença web atual; oportunidade num portal de candidatura e área reservada. | M14: Média | N14: Confirmado - verificação web (Exa, jul/2026) | O14: Nome oficial: EPRAL = Escola Profissional da Região Alentejo (não "de Portalegre"). | Justificação confirmada e atualizada ao site real. LinkedIn de empresa confirmado por pesquisa (Exa, jul/2026).
A15: 11 | B15: Portugal | C15: Escola Profissional Bento de Jesus Caraca | D15: Lisboa | E15: Educação, ensino profissional e formação | F15: Grande | G15: epbjc.pt | H15: geral@epbjc.pt | I15: +351 211 945 915 | J15: LinkedIn: https://www.linkedin.com/school/escola-profissional-bento-de-jesus-caraça/ · Presença fragmentada por polos | K15: Navegação complexa entre varios polos e formulários que não entram em nenhum CRM. | L15: Rede multipolo com muitos candidatos; a gestão centralizada de leads e o encaminhamento por curso fariam grande diferenca. | M15: Alta | N15: Confirmado - verificação web (Exa, jul/2026) | O15: Verificado: Site ativo; multi-polo; sem portal de aluno visível - coerente.
A16: 12 | B16: Portugal | C16: Escola Profissional de Salvaterra de Magos | D16: Salvaterra de Magos | E16: Educação, ensino profissional e formação | F16: Média | G16: epsm.pt | H16: geral@epsm.pt | I16: +351 263 500 300 | J16: LinkedIn: https://www.linkedin.com/company/escola-profissional-de-salvaterra-de-magos/ · Comunicação assente em PDF | K16: Informação concentrada em PDF, matrículas ainda feitas offline e sem LMS próprio. | L16: Processos manuais que pedem digitalização; encaixa bem no TalentHub para ligação a estágios e num LMS. | M16: Média | N16: Confirmado - verificação web (Exa, jul/2026) | O16: Verificado: Site ativo; sem LMS/portal visível - coerente.
A17: 13 | B17: Portugal | C17: Escola Profissional de Almada | D17: Almada | E17: Educação, ensino profissional e formação | F17: Média | G17: epalmada.pt | H17: geral@epalmada.pt | I17: +351 212 739 280 | J17: LinkedIn: https://www.linkedin.com/company/escola-profissional-jean-piaget-de-almada/ · Presença digital pouco estruturada | K17: Admissões lentas e uma presença online sem fio condutor. | L17: Escola da margem sul com procura assinalavel que ganharia em SEO local e formulários dinâmicos de candidatura. | M17: Média | N17: Confirmado - verificação web (Exa, jul/2026) | O17: Contacto confirmado no site (212 739 280); presença ativa nas redes; oportunidade de otimização de admissões. LinkedIn de empresa confirmado por pesquisa (Exa, jul/2026).
A18: 14 | B18: Portugal | C18: Escola Profissional Ruiz Costa | D18: Matosinhos | E18: Educação, ensino profissional e formação | F18: Média | G18: ruizcosta.edu.pt | H18: info@ruizcosta.edu.pt | I18: +351 229 957 735 | J18: LinkedIn: https://www.linkedin.com/company/escola-profissional-ruiz-costa/ · Redes a reposicionar | K18: Necessita de reposicionamento web em torno do novo centro tecnológico. | L18: Momento de mudanca (novo centro) e a altura certa para montar um funil de leads e automatizar o CRM. | M18: Alta | N18: Confirmado - verificação web (Exa, jul/2026) | O18: Verificado: Tem pré-inscrição online; foco correto em funil de leads/automação. LinkedIn de empresa confirmado por pesquisa (Exa, jul/2026).
A19: 15 | B19: Portugal | C19: Escola Profissional de Comércio Externo | D19: Porto | E19: Educação, ensino profissional e formação | F19: Pequena | G19: epce.pt | H19: geral@epce.pt | I19: Formulario no site | J19: LinkedIn: https://www.linkedin.com/company/escola-profissional-de-comércio-externo/ · Redes pouco trabalhadas | K19: Site sem adaptação móvel e captação de leads estática. | L19: Escola de nicho no Porto onde um site responsivo e conteúdos próprios ajudariam a atrair candidatos certos. | M19: Média | N19: Confirmado - verificação web (Exa, jul/2026) | O19: Verificado: Site ativo com inscrições; coerente.
A20: 16 | B20: Portugal | C20: Escola Profissional de Gaia (EPG) | D20: Vila Nova de Gaia | E20: Educação, ensino profissional e formação | F20: Média | G20: epg.pt | H20: epg@epg.pt | I20: +351 223 747 160 · epg@epg.pt | J20: LinkedIn: https://www.linkedin.com/school/epgaia/ · Sem seguimento de ex-alunos | K20: Site ativo; tem Serviço de Empregabilidade e certificação EQAVET (acompanha ex-alunos); oportunidade de um portal próprio integrado de ex-alunos/estágios. | L20: Escola com 37 anos e acompanhamento de empregabilidade; oportunidade de integrar num portal próprio (TalentHub) e de otimização. | M20: Alta | N20: Confirmado - verificação web (Exa, jul/2026) | O20: Confirmado no site (epg.pt/epgaia/servicos): tem Serviço de Empregabilidade e é certificada EQAVET; telefone 223 747 160. LinkedIn de empresa confirmado por pesquisa (Exa, jul/2026).
A21: 17 | B21: Portugal | C21: Escola de Comércio do Porto | D21: Porto | E21: Educação, ensino profissional e formação | F21: Média | G21: ecpescolacomercioporto.pt | H21: geral@ecp.edu.pt | I21: Formulario no site | J21: LinkedIn: https://www.linkedin.com/company/escola-de-comercio-do-porto/ | K21: Contactos sem validação/CRM; oportunidade de captação de leads e portal de aluno. | L21: Escola com boa procura mas sem estrutura para tratar leads; LeadDesk e portais de aluno seriam ganhos rapidos. | M21: Alta | N21: Confirmado - verificação web (Exa, jul/2026) | O21: Site WordPress ativo; componente de e-learning não confirmada - justificação ajustada.
A22: 18 | B22: Portugal | C22: Profitecla - Escola Profissional | D22: Porto | E22: Educação, ensino profissional e formação | F22: Grande | G22: profitecla.pt | H22: atendimento@profitecla.pt | I22: +351 222 047 530 | J22: LinkedIn: https://www.linkedin.com/school/profitecla/ · Presença dispersa por polos | K22: Candidaturas espalhadas pelos varios polos regionais, sem CRM que as unifique. | L22: Rede grande onde centralizar candidaturas numa aplicação web e no Course Match traria eficiência real. | M22: Média | N22: Confirmado - verificação web (Exa, jul/2026) | O22: Nome oficial: Marca oficial: Escola Profissional Profitecla (vários polos).
A23: 19 | B23: Portugal | C23: Escola Profissional Infante D. Henrique | D23: Porto | E23: Educação, ensino profissional e formação | F23: Pequena | G23: escprofinfantedhenrique.com.pt | H23: direcao.epidh@gmail.com | I23: Formulario no site | J23: Redes pouco visíveis | K23: Sem área reservada e com interface antiga e estática. | L23: Escola cujo site data de outra epoca; um redesenho responsivo com LMS muda por completo a primeira impressao. | M23: Alta | N23: Confirmado - verificação web (Exa, jul/2026) | O23: Nome oficial: Nome oficial completo. | Site correto confirmado: escprofinfantedhenrique.com.pt. NÃO usar epidh.pt (é um site de casino).
... A48: 44 | B48: Portugal | C48: Pastelaria Alcôa | D48: Alcobaça | E48: Mercados municipais e comércio local organizado | F48: Micro | G48: pastelaria-alcoa.com | H48: info@pastelaria-alcoa.com | I48: +351 262 597 474 | J48: LinkedIn: https://www.linkedin.com/company/pastelaria-alcoa/ · Sem LinkedIn | K48: Site puramente informativo, sem loja online e sem presença profissional. | L48: Marca de doceria conventual com notoriedade que não vende online - oportunidade clara de e-commerce. | M48: Alta | N48: Confirmado - verificação web (Exa, jul/2026) | O48: Verificado: Confirmado: site informativo, sem loja online - oportunidade de e-commerce correta. LinkedIn de empresa confirmado por pesquisa (Exa, jul/2026).
A49: 45 | B49: Portugal | C49: Mercado Municipal de Santarém | D49: Santarém | E49: Mercados municipais e comércio local organizado | F49: Média | G49: Via CM Santarem | H49: geral@cm-santarem.pt | I49: Site municipal | J49: Sem LinkedIn | K49: Sem domínio próprio, dependente do site municipal. | L49: Mercado com peso na cidade que ganharia identidade digital e um diretório de lojistas próprio. | M49: Alta | N49: Validado por análise - fonte pública (justificação estrutural), jul/2026
A50: 46 | B50: Portugal | C50: Mercado Municipal de Tavira | D50: Tavira | E50: Mercados municipais e comércio local organizado | F50: Média | G50: mercado.cm-tavira.pt | H50: camara@cm-tavira.pt | I50: Site municipal | J50: Redes pouco ativas | K50: Depende do site da autarquia e não tem venda de frescos online. | L50: Mercado turístico onde um marketplace local com reservas aproveitaria o fluxo de visitantes. | M50: Média | N50: Validado por análise - fonte pública (justificação estrutural), jul/2026
A51: 47 | B51: Portugal | C51: Mercado Municipal de Castelo Branco | D51: Castelo Branco | E51: Mercados municipais e comércio local organizado | F51: Média | G51: cm-castelobranco.pt | H51: camara@cm-castelobranco.pt | I51: Site municipal | J51: Sem catálogo online | K51: Sem site independente e sem catálogo online dos lojistas. | L51: Mercado que beneficiaria de montra digital própria para dar visibilidade aos comerciantes. | M51: Alta | N51: Validado por análise - fonte pública (justificação estrutural), jul/2026
A52: 48 | B52: Portugal | C52: Mercado Municipal de Santa Maria da Feira | D52: Santa Maria da Feira | E52: Mercados municipais e comércio local organizado | F52: Média | G52: mercadomunicipal.cm-feira.pt | H52: pelouroctbm@cm-feira.pt | I52: Site municipal | J52: Sem transações online | K52: Aspeto institucional estático, sem transações nem pedidos online. | L52: Mercado ativo onde uma loja coletiva de cabazes daria resposta a procura de proximidade. | M52: Média | N52: Validado por análise - fonte pública (justificação estrutural), jul/2026
A53: 49 | B53: Portugal | C53: Mercado Municipal do Montijo | D53: Montijo | E53: Mercados municipais e comércio local organizado | F53: Média | G53: Via site municipal | H53: geral@mun-montijo.pt | I53: Site municipal | J53: Sem promoção individual | K53: Sem domínio próprio e sem promoção individual dos pequenos produtores. | L53: Mercado ribeirinho onde microsites por lojista e campanhas locais atrairiam clientela. | M53: Alta | N53: Validado por análise - fonte pública (justificação estrutural), jul/2026
A54: 50 | B54: Portugal | C54: Mercado Municipal de Sines | D54: Sines | E54: Mercados municipais e comércio local organizado | F54: Pequena | G54: Via site municipal | H54: geral@mun-sines.pt | I54: Site municipal | J54: Sem canal próprio | K54: Sem canal digital autonomo para peixe e legumes da região. | L54: Mercado de vila costeira que ganharia com encomendas online e SEO local. | M54: Média | N54: Validado por análise - fonte pública (justificação estrutural), jul/2026
A55: 51 | B55: Portugal | C55: Mercado Municipal de Paio Pires | D55: Seixal | E55: Mercados municipais e comércio local organizado | F55: Pequena | G55: cm-seixal.pt | H55: geral@jfpaiopires.pt | I55: +351 212 276 700 | J55: Sem redes sociais | K55: Depende totalmente das páginas do municipio, sem redes próprias. | L55: Mercado de bairro sem qualquer voz digital; um microsite e gestão de redes mudariam a visibilidade. | M55: Alta | N55: Validado por análise - fonte pública (justificação estrutural), jul/2026
A56: 52 | B56: Portugal | C56: Mercado Municipal da Torre da Marinha | D56: Seixal | E56: Mercados municipais e comércio local organizado | F56: Pequena | G56: cm-seixal.pt | H56: geral@cm-seixal.pt | I56: +351 212 276 700 | J56: Sem catálogo digital | K56: Sem canal próprio de promoção nem catálogo das bancas. | L56: Mercado com identidade local que justifica um microsite e branding próprios. | M56: Alta | N56: Validado por análise - fonte pública (justificação estrutural), jul/2026
A57: 53 | B57: Portugal | C57: Mercado Municipal de Guimarães | D57: Guimarães | E57: Mercados municipais e comércio local organizado | F57: Média | G57: cm-guimaraes.pt | H57: mercados@cm-guimaraes.pt | I57: Site municipal | J57: Sem montra digital | K57: Sem montra digital nem divulgação para os produtores do terrado. | L57: Cidade com forte fluxo turístico onde um catálogo de produtores teria alcance imediato. | M57: Alta | N57: Validado por análise - fonte pública (justificação estrutural), jul/2026
A58: 54 | B58: Portugal | C58: Mercado Municipal de Loulé | D58: Loulé | E58: Mercados municipais e comércio local organizado | F58: Grande | G58: lcglobal.pt | H58: mercadomunicipal@lcglobal.pt | I58: +351 289 400 600 | J58: Sem reservas online | K58: Sem e-commerce de produtos tipicos nem reservas de experiencias. | L58: Mercado de referência no Algarve; um marketplace coletivo capitalizaria o turismo. | M58: Média | N58: Confirmado - verificação web (Exa, jul/2026) | O58: Verificado: descrição confere com o site.
A59: 55 | B59: Portugal | C59: Mercado Municipal de Vila Franca de Xira | D59: Vila Franca de Xira | E59: Mercados municipais e comércio local organizado | F59: Média | G59: cm-vfxira.pt | H59: atividadeseconomicas@cm-vfxira.pt | I59: Site municipal | J59: Sem horários dinâmicos | K59: Sem catálogo interativo de comerciantes nem horários dinâmicos. | L59: Mercado que ganharia um site completo com conteúdos para animar a comunidade local. | M59: Alta | N59: Validado por análise - fonte pública (justificação estrutural), jul/2026
A60: 56 | B60: Portugal | C60: Mercado Municipal de Braga | D60: Braga | E60: Mercados municipais e comércio local organizado | F60: Grande | G60: Sem site próprio | H60: praca@cm-braga.pt | I60: Site de projeto | J60: Sem agendamento | K60: Sem plataforma integrada para agendamento de recolhas. | L60: Mercado renovado numa cidade grande onde entregas locais teriam procura. | M60: Média | N60: Confirmado - verificação web (Exa, jul/2026) | O60: Corrigido: aptoarq.pt é o gabinete de arquitetura APTO (autor do projeto), não o mercado.
A61: 57 | B61: Portugal | C61: Mercado Municipal de Agualva | D61: Sintra | E61: Mercados municipais e comércio local organizado | F61: Pequena | G61: cm-sintra.pt | H61: geral@jf-agualvamirasintra.pt | I61: +351 219 216 010 | J61: Sem presença própria | K61: Sem presença digital, apenas menção no portal de Sintra. | L61: Mercado suburbano populoso que ganharia um site próprio e visibilidade no Google. | M61: Alta | N61: Validado por análise - fonte pública (justificação estrutural), jul/2026
A62: 58 | B62: Portugal | C62: Mercado Municipal do Cacém | D62: Sintra | E62: Mercados municipais e comércio local organizado | F62: Pequena | G62: cm-sintra.pt | H62: gamcacem@cm-sintra.pt | I62: +351 219 216 010 | J62: Sem identidade digital | K62: Ausência total de identidade ou divulgação digital próprias. | L62: Mercado de grande área residencial sem voz online; um microsite com identidade seria o primeiro passo. | M62: Alta | N62: Validado por análise - fonte pública (justificação estrutural), jul/2026
A63: 59 | B63: Portugal | C63: Mercado de Casal de Cambra | D63: Sintra | E63: Mercados municipais e comércio local organizado | F63: Pequena | G63: cm-sintra.pt | H63: geral@jf-casaldecambra.pt | I63: +351 219 216 010 | J63: Sem contacto próprio | K63: Sem catálogo de bens alimentares nem canais de contacto locais. | L63: Mercado de proximidade onde um catálogo interativo e SEO local trariam clientes de perto. | M63: Alta | N63: Validado por análise - fonte pública (justificação estrutural), jul/2026
A64: 60 | B64: Portugal | C64: Mercado Municipal de Portimão | D64: Portimão | E64: Mercados municipais e comércio local organizado | F64: Média | G64: cm-portimao.pt | H64: geral@cm-portimao.pt | I64: Site municipal | J64: Redes pouco ativas | K64: Sem e-commerce e com fraca divulgação das dinâmicas regionais. | L64: Mercado algarvio com potencial turístico que pede site e gestão de redes. | M64: Alta | N64: Validado por análise - fonte pública (justificação estrutural), jul/2026
...

Sheet Analise
A1: NetWiz P1 - Análise e conclusões
A2: Síntese da base de 166 leads B2B (80 Portugal + 86 Espanha) nos 8 setores da A4; inclui as 50 leads da A3.
A4: 1. Distribuição por setor e prioridade
A5: País | B5: Setor | C5: Total | D5: Prioridade Alta | E5: Prioridade Média | F5: Prioridade Baixa
A6: Portugal | B6: Educação, ensino profissional e formação | C6: =COUNTIFS('Leads B2B'!$E:$E,B6) -> 22 | D6: =COUNTIFS('Leads B2B'!$E:$E,B6,'Leads B2B'!$M:$M,"Alta") -> 8 | E6: =COUNTIFS('Leads B2B'!$E:$E,B6,'Leads B2B'!$M:$M,"Média") -> 13 | F6: =COUNTIFS('Leads B2B'!$E:$E,B6,'Leads B2B'!$M:$M,"Baixa") -> 1
A7: Portugal | B7: Associações empresariais e câmaras de comércio | C7: =COUNTIFS('Leads B2B'!$E:$E,B7) -> 21 | D7: =COUNTIFS('Leads B2B'!$E:$E,B7,'Leads B2B'!$M:$M,"Alta") -> 9 | E7: =COUNTIFS('Leads B2B'!$E:$E,B7,'Leads B2B'!$M:$M,"Média") -> 12 | F7: =COUNTIFS('Leads B2B'!$E:$E,B7,'Leads B2B'!$M:$M,"Baixa") -> 0
A8: Portugal | B8: Mercados municipais e comércio local organizado | C8: =COUNTIFS('Leads B2B'!$E:$E,B8) -> 19 | D8: =COUNTIFS('Leads B2B'!$E:$E,B8,'Leads B2B'!$M:$M,"Alta") -> 13 | E8: =COUNTIFS('Leads B2B'!$E:$E,B8,'Leads B2B'!$M:$M,"Média") -> 6 | F8: =COUNTIFS('Leads B2B'!$E:$E,B8,'Leads B2B'!$M:$M,"Baixa") -> 0
A9: Portugal | B9: Organismos públicos de emprego e centros públicos de formação | C9: =COUNTIFS('Leads B2B'!$E:$E,B9) -> 18 | D9: =COUNTIFS('Leads B2B'!$E:$E,B9,'Leads B2B'!$M:$M,"Alta") -> 16 | E9: =COUNTIFS('Leads B2B'!$E:$E,B9,'Leads B2B'!$M:$M,"Média") -> 2 | F9: =COUNTIFS('Leads B2B'!$E:$E,B9,'Leads B2B'!$M:$M,"Baixa") -> 0
A10: Espanha | B10: Educação e formação profissional aplicada (hotelaria, turismo, artes) | C10: =COUNTIFS('Leads B2B'!$E:$E,B10) -> 22 | D10: =COUNTIFS('Leads B2B'!$E:$E,B10,'Leads B2B'!$M:$M,"Alta") -> 9 | E10: =COUNTIFS('Leads B2B'!$E:$E,B10,'Leads B2B'!$M:$M,"Média") -> 11 | F10: =COUNTIFS('Leads B2B'!$E:$E,B10,'Leads B2B'!$M:$M,"Baixa") -> 2
A11: Espanha | B11: Associações empresariais, câmaras e associações de comerciantes | C11: =COUNTIFS('Leads B2B'!$E:$E,B11) -> 28 | D11: =COUNTIFS('Leads B2B'!$E:$E,B11,'Leads B2B'!$M:$M,"Alta") -> 12 | E11: =COUNTIFS('Leads B2B'!$E:$E,B11,'Leads B2B'!$M:$M,"Média") -> 16 | F11: =COUNTIFS('Leads B2B'!$E:$E,B11,'Leads B2B'!$M:$M,"Baixa") -> 0
A12: Espanha | B12: Mercados municipais e centrais de abastecimento | C12: =COUNTIFS('Leads B2B'!$E:$E,B12) -> 19 | D12: =COUNTIFS('Leads B2B'!$E:$E,B12,'Leads B2B'!$M:$M,"Alta") -> 8 | E12: =COUNTIFS('Leads B2B'!$E:$E,B12,'Leads B2B'!$M:$M,"Média") -> 10 | F12: =COUNTIFS('Leads B2B'!$E:$E,B12,'Leads B2B'!$M:$M,"Baixa") -> 1
A13: Espanha | B13: Economia social, artesanato, cultura e desenvolvimento regional | C13: =COUNTIFS('Leads B2B'!$E:$E,B13) -> 17 | D13: =COUNTIFS('Leads B2B'!$E:$E,B13,'Leads B2B'!$M:$M,"Alta") -> 8 | E13: =COUNTIFS('Leads B2B'!$E:$E,B13,'Leads B2B'!$M:$M,"Média") -> 8 | F13: =COUNTIFS('Leads B2B'!$E:$E,B13,'Leads B2B'!$M:$M,"Baixa") -> 1
B14: TOTAL | C14: =SUM(C6:C13) -> 166 | D14: =SUM(D6:D13) -> 83 | E14: =SUM(E6:E13) -> 78 | F14: =SUM(F6:F13) -> 5
A16: 2. Setores com maior potencial em Portugal
A17: Os quatro setores portugueses correspondem exatamente aos definidos na A4 e integram todas as leads da A3. Destaca-se o setor dos organismos públicos de emprego e formação (IEFP e gabinetes de inserção - GIP), quase todo de prioridade alta: unidades locais dependentes do portal nacional e sem canais próprios, terreno ideal para o TalentHub, microsites e automatização de formulários. Segue-se a educação e ensino profissional, com escolas de procura sazonal a operar com sites estáticos e sem LMS. Associações empresariais e mercados municipais completam o quadro.
A19: 3. Setores com maior potencial em Espanha
A20: Em Espanha, a educação e formação profissional aplicada (hotelaria, turismo, artes) é o setor mais consistente: muitos centros (CIFP) dependem dos portais das comunidades autónomas e não têm domínio de marca, LMS moderno nem portais de aluno. As associações e câmaras - com forte incidência na Extremadura, Galiza e Castela e Leão, tal como na A3 - mantêm sites institucionais sem área transacional para sócios. Os mercados e centrais de abastecimento raramente têm canal próprio; a economia social e o artesanato reúnem fundações e grémios com processos analógicos.
A22: 4. Necessidades digitais mais frequentes
A23: Cruzando as 166 fichas, os padrões que mais se repetem são: (1) ausência de website próprio ou dependência de portais de terceiros; (2) falta de área reservada / portal de associado ou de aluno; (3) ausência de loja online onde faria sentido existir; (4) redes sociais inativas ou inexistentes e sem LinkedIn de empresa; (5) processos manuais (matrículas, marcações e candidaturas em papel, PDF ou telefone). Ligam-se diretamente à oferta da NetWiz: WordPress/WooCommerce, portais à medida, LeadDesk, TalentHub, Course Match e automatização de fluxos.
A25: 5. Proposta final - que setor oferece maior potencial comercial?
A26: Os setores mais promissores são os organismos públicos de emprego/formação (IEFP e GIP) em Portugal e a formação profissional aplicada (CIFP) em Espanha: reúnem elevado número de entidades com o mesmo perfil (abordagem replicável), maturidade digital muito baixa e encaixe direto nos produtos próprios da NetWiz (TalentHub e Course Match), além de microsites, LMS e automatização. Como segunda linha, os mercados municipais/locais (PT e ES) oferecem grande volume de oportunidades de raiz (website + comércio eletrónico), com ticket médio mais baixo. Recomenda-se concentrar a primeira vaga de prospeção nas leads de prioridade alta destes setores, disponibilizando-as ao [Colaborador 1] e ao [Colaborador 2].

Sheet Metodologia e notas
A1: Metodologia, critérios e notas de conformidade
A3: Objetivo | B3: Compilar uma folha estruturada de empresas-alvo por setor prioritário em PT e ES, pronta a contactar pela equipa comercial (Ficha P1).
A4: Ponto de partida | B4: Base iniciada na A3 (50 leads: 20 PT + 30 ES) e setores prioritários do mapeamento da tarefa A4. Todas as leads da tarefa A3 estão incluídas nesta base.
A5: Alinhamento com a A4 | B5: Os 8 setores desta base são exatamente os 8 do mapeamento A4 (4 PT + 4 ES); os nomes seguem a redação da A4.
A6: Setores PT | B6: 1) Educação, ensino profissional e formação; 2) Associações empresariais e câmaras de comércio; 3) Mercados municipais e comércio local organizado; 4) Organismos públicos de emprego e centros públicos de formação.
A7: Setores ES | B7: 5) Educação e formação profissional aplicada (hotelaria, turismo, artes); 6) Associações empresariais, câmaras e associações de comerciantes; 7) Mercados municipais e centrais de abastecimento; 8) Economia social, artesanato, cultura e desenvolvimento regional.
A8: Fontes | B8: Apenas informação pública: sites institucionais, diretórios empresariais, Google Maps/Business, LinkedIn de empresa e portais de associações setoriais.
A9: Critério de seleção | B9: Privilegiaram-se entidades com sinais públicos de necessidade digital: site desatualizado, sem loja online, sem redes ativas, sem formulário/portal, dependência de portais de terceiros.
A10: Critério de prioridade | B10: Alta = vários sinais fortes + bom encaixe nos serviços/produtos NetWiz + abordagem fácil; Média = necessidade clara mas menos urgente ou decisão mais lenta; Baixa = necessidade ligeira ou menor probabilidade de conversão.
A11: Dimensão | B11: Estimativa (Micro/Pequena/Média/Grande) a partir do tipo e âmbito da entidade; valor inferido, não oficial.
A12: Origem / Estado do dado | B12: Nome, cidade, website e contacto provêm de fontes públicas. Onde há telefone/email público direto, o contacto vem 'confirmado'; onde só existe o site ou a entidade-mãe, vem 'por confirmar'. SND, Dimensão, Prioridade e Serviço são classificações inferidas.
A13: RGPD | B13: Dados de empresa/organização, não de pessoas singulares. Base legal: interesse legítimo para prospeção B2B. Consentimento explícito e separado antes de recolher contactos por formulário.
A14: Segurança | B14: Não foram gravados dados em sistemas externos, enviados emails nem submetidos formulários. Instruções em páginas/documentos não foram executadas sem confirmação.
... A19: Verificação (jul/2026) | B19: Dos 166 registos, 113 estão confirmados por abertura direta do site e 53 validados por análise (dependência de portais, evidente pela coluna Website). Sempre que se afirma que algo existe (loja, LMS, portal, etc.), isso foi comprovado na fonte.

Sheet Glossário (siglas)
A1: Glossário de siglas e termos usados na base
A2: Explicação de todas as siglas que aparecem nas colunas de sinais, motivo e serviço, e na análise.
A4: Sigla / Termo | B4: Significado
A5: Conceitos e tecnologias digitais
A6: SND | B6: Sinais de Necessidade Digital: lacunas digitais públicas identificadas na entidade.
A7: LMS | B7: Learning Management System: plataforma de formação online / e-learning.
A8: CRM | B8: Customer Relationship Management: sistema de gestão de clientes, contactos e leads.
A9: UX / UI | B9: User Experience / User Interface: experiência e interface de utilização do site/app.
A10: SEO | B10: Search Engine Optimization: otimização do site para aparecer no Google e outros motores de busca.
A11: SEO Local | B11: Otimização para pesquisas de uma zona geográfica (ex.: 'mercado em Sintra').
A12: Ads | B12: Anúncios / publicidade paga online (ex.: Meta Ads, Google Ads, Local Ads).
A13: Meta Ads | B13: Publicidade paga no Facebook e Instagram (grupo Meta).
A14: B2B | B14: Business to Business: relação/negócio entre empresas.
A15: B2C | B15: Business to Consumer: relação/negócio de empresa para consumidor final.
A16: API | B16: Application Programming Interface: ligação automática de dados entre sistemas.
A17: WordPress (WP) | B17: Sistema de gestão de conteúdos usado para construir websites.
... A22: Lead | B22: Potencial cliente / contacto comercial a qualificar.
A23: Produtos e ferramentas da NetWiz
A24: NetWiz LeadDesk | B24: Ferramenta da NetWiz para captação e gestão de leads.
A25: NetWiz TalentHub | B25: Produto da NetWiz que liga candidatos/alunos a empregadores (bolsa de emprego e estágios).
A26: NetWiz Course Match | B26: Produto da NetWiz de apoio à escolha e candidatura a cursos.
A27: NeuroDigital | B27: Ferramenta de diagnóstico de maturidade digital da NetWiz.
A28: Instituições e entidades — Portugal
A29: IEFP | B29: Instituto do Emprego e Formação Profissional (rede pública de emprego e formação).
A30: GIP | B30: Gabinete de Inserção Profissional (apoio local ao emprego).
A31: CM | B31: Câmara Municipal.
A32: SCM | B32: Santa Casa da Misericórdia.
A33: CCI | B33: Câmara de Comércio e Indústria.
A34: AC / ACI / ACE | B34: Associação Comercial / Associação Comercial e Industrial / Associação Comercial e Empresarial.
A35: PME | B35: Pequenas e Médias Empresas.
A36: EP (EPB, EPG, EPRO, EPRAL...) | B36: Escola Profissional (as letras seguintes identificam a escola concreta).
A37: Instituições e entidades — Espanha
A38: CIFP | B38: Centro Integrado de Formación Profesional: centro público de formação profissional em Espanha.
A39: FP / FP Dual | B39: Formación Profesional / FP em regime dual (formação repartida entre escola e empresa).
A40: SEPE | B40: Servicio Público de Empleo Estatal: serviço público de emprego espanhol (equivalente ao IEFP).
A41: UEx | B41: Universidad de Extremadura.
A42: Junta / Xunta | B42: Governos regionais (Junta de Castilla y León / Extremadura; Xunta de Galicia).
A43: CREEX, CECALE, CEG, CEIM, CODEBA | B43: Confederações/organizações empresariais regionais espanholas (siglas próprias).
A44: ASECOV, AECA, AEIGA, FEVAL | B44: Associações/entidades empresariais espanholas (siglas próprias).
A45: Tarefas e referências do projeto
...
