Workbook

Sheet Oferta Formativa PT
A1: Nome da Instituição | B1: País | C1: Cidade | D1: Tipo de Instituição (Pública/Privada) | E1: Tipologia do Curso | F1: Nome do Curso | G1: Área Científica | H1: Campus / Unidade / Faculdade | I1: Link Oficial do Curso | J1: Duração | K1: Modalidade | L1: Idioma | M1: Observações relevantes | N1: Região (análise)
A2: Atlântica – Instituto Universitário | B2: Portugal | C2: Oeiras | D2: Privada | E2: Licenciatura | F2: Ciências da Nutrição | G2: Terapia e Reabilitação | H2: Campus Atlântica, Fábrica da Pólvora de Barcarena | I2: https://www.google.com/search?q=site%3Auatlantica.pt%20Ci%C3%AAncias%20da%20Nutri%C3%A7%C3%A3o%20licenciatura | J2: 4 ano(s) (240 ECTS) | K2: Presencial | L2: Português | N2: A.M. Lisboa
A3: Atlântica – Instituto Universitário | B3: Portugal | C3: Oeiras | D3: Privada | E3: Licenciatura | F3: Design UX/UI | G3: Design | H3: Campus Atlântica, Fábrica da Pólvora de Barcarena | I3: https://www.google.com/search?q=site%3Auatlantica.pt%20Design%20UX/UI%20licenciatura | J3: 3 ano(s) (180 ECTS) | K3: Presencial | L3: Português | N3: A.M. Lisboa
A4: Atlântica – Instituto Universitário | B4: Portugal | C4: Oeiras | D4: Privada | E4: Licenciatura | F4: Engenharia Aeronáutica | G4: Construção e Reparação de Veículos a Motor (aeronáutica) | H4: Campus Atlântica, Fábrica da Pólvora de Barcarena | I4: https://www.google.com/search?q=site%3Auatlantica.pt%20Engenharia%20Aeron%C3%A1utica%20licenciatura | J4: 3 ano(s) (180 ECTS) | K4: Presencial | L4: Português | N4: A.M. Lisboa
A5: Atlântica – Instituto Universitário | B5: Portugal | C5: Oeiras | D5: Privada | E5: Licenciatura | F5: Engenharia Mecânica | G5: Metalurgia e Metalomecânica | H5: Campus Atlântica, Fábrica da Pólvora de Barcarena | I5: https://www.google.com/search?q=site%3Auatlantica.pt%20Engenharia%20Mec%C3%A2nica%20licenciatura | J5: 3 ano(s) (180 ECTS) | K5: Presencial | L5: Português | N5: A.M. Lisboa
A6: Atlântica – Instituto Universitário | B6: Portugal | C6: Oeiras | D6: Privada | E6: Licenciatura | F6: Engenharia de Materiais | G6: Metalurgia e Metalomecânica | H6: Campus Atlântica, Fábrica da Pólvora de Barcarena | I6: https://www.google.com/search?q=site%3Auatlantica.pt%20Engenharia%20de%20Materiais%20licenciatura | J6: 3 ano(s) (180 ECTS) | K6: Presencial | L6: Português | M6: Em processo de extinção | N6: A.M. Lisboa
A7: Atlântica – Instituto Universitário | B7: Portugal | C7: Oeiras | D7: Privada | E7: Licenciatura | F7: Gestão | G7: Gestão e Administração | H7: Campus Atlântica, Fábrica da Pólvora de Barcarena | I7: https://www.google.com/search?q=site%3Auatlantica.pt%20Gest%C3%A3o%20licenciatura | J7: 3 ano(s) (180 ECTS) | K7: Presencial | L7: Português | N7: A.M. Lisboa
A8: Atlântica – Instituto Universitário | B8: Portugal | C8: Oeiras | D8: Privada | E8: Licenciatura | F8: Gestão da Segurança, Emergência e Proteção Civil | G8: Proteção de Pessoas e Bens | H8: Campus Atlântica, Fábrica da Pólvora de Barcarena | I8: https://www.google.com/search?q=site%3Auatlantica.pt%20Gest%C3%A3o%20da%20Seguran%C3%A7a%2C%20Emerg%C3%AAncia%20e%20Prote%C3%A7%C3%A3o%20Civil%20licenciatura | J8: 3 ano(s) (180 ECTS) | K8: Presencial | L8: Português | N8: A.M. Lisboa
A9: Atlântica – Instituto Universitário | B9: Portugal | C9: Oeiras | D9: Privada | E9: Licenciatura | F9: Gestão de Sistemas e Computação | G9: Ciências Informáticas | H9: Campus Atlântica, Fábrica da Pólvora de Barcarena, 2730‑036 Barcarena, Oeiras | I9: https://www.google.com/search?q=site%3Auatlantica.pt%20Gest%C3%A3o%20de%20Sistemas%20e%20Computa%C3%A7%C3%A3o%20licenciatura | J9: 3 ano(s) (180 ECTS) | K9: Presencial | L9: Português | N9: A.M. Lisboa
A10: Atlântica – Instituto Universitário | B10: Portugal | C10: Oeiras | D10: Privada | E10: Licenciatura | F10: Gestão do Transporte Aéreo | G10: Serviços de Transporte | H10: Campus Atlântica, Fábrica da Pólvora de Barcarena | I10: https://www.google.com/search?q=site%3Auatlantica.pt%20Gest%C3%A3o%20do%20Transporte%20A%C3%A9reo%20licenciatura | J10: 3 ano(s) (180 ECTS) | K10: Presencial | L10: Português | N10: A.M. Lisboa
A11: Atlântica – Instituto Universitário | B11: Portugal | C11: Oeiras | D11: Privada | E11: Licenciatura | F11: Gestão em Saúde | G11: Gestão e Administração | H11: Campus Atlântica, Fábrica da Pólvora de Barcarena | I11: https://www.google.com/search?q=site%3Auatlantica.pt%20Gest%C3%A3o%20em%20Sa%C3%BAde%20licenciatura | J11: 3 ano(s) (180 ECTS) | K11: Presencial | L11: Português | N11: A.M. Lisboa
A12: Atlântica – Instituto Universitário | B12: Portugal | C12: Oeiras | D12: Privada | E12: Mestrado | F12: Engenharia de Materiais | G12: Metalurgia e Metalomecânica | H12: Campus Atlântica, Barcarena | I12: https://www.google.com/search?q=site%3Auatlantica.pt%20Engenharia%20de%20Materiais%20mestrado | J12: 2 ano(s) (120 ECTS) | K12: Presencial | L12: Português | N12: A.M. Lisboa
A13: Atlântica – Instituto Universitário | B13: Portugal | C13: Oeiras | D13: Privada | E13: Mestrado | F13: Engenharia e Gestão de Manutenção Aeronáutica | G13: Construção e Reparação de Veículos a Motor | H13: Campus Atlântica, Barcarena | I13: https://www.google.com/search?q=site%3Auatlantica.pt%20Engenharia%20e%20Gest%C3%A3o%20de%20Manuten%C3%A7%C3%A3o%20Aeron%C3%A1utica%20mestrado | J13: 2 ano(s) (120 ECTS) | K13: Presencial | L13: Português | N13: A.M. Lisboa
A14: Atlântica – Instituto Universitário | B14: Portugal | C14: Oeiras | D14: Privada | E14: Mestrado | F14: Engenharia e Gestão de Sistemas de Fabrico | G14: Engenharia e Técnicas Afins | H14: Campus Atlântica, Barcarena | I14: https://www.google.com/search?q=site%3Auatlantica.pt%20Engenharia%20e%20Gest%C3%A3o%20de%20Sistemas%20de%20Fabrico%20mestrado | J14: 2 ano(s) (120 ECTS) | K14: Presencial | L14: Português | M14: Em processo de extinção | N14: A.M. Lisboa
A15: Atlântica – Instituto Universitário | B15: Portugal | C15: Oeiras | D15: Privada | E15: Mestrado | F15: Gestão | G15: Gestão e Administração | H15: Campus Atlântica, Barcarena | I15: https://www.google.com/search?q=site%3Auatlantica.pt%20Gest%C3%A3o%20mestrado | J15: 2 ano(s) (120 ECTS) | K15: Presencial | L15: Português | N15: A.M. Lisboa
A16: Atlântica – Instituto Universitário | B16: Portugal | C16: Oeiras | D16: Privada | E16: Mestrado | F16: Gestão (registo antigo) | G16: Gestão e Administração | H16: Campus Atlântica, Barcarena | I16: https://www.google.com/search?q=site%3Auatlantica.pt%20Gest%C3%A3o%20%28registo%20antigo%29%20mestrado | J16: 2 ano(s) (120 ECTS) | K16: Presencial | L16: Português | M16: Em processo de extinção | N16: A.M. Lisboa
A17: Atlântica – Instituto Universitário | B17: Portugal | C17: Oeiras | D17: Privada | E17: Mestrado | F17: Gestão de Sistemas e Tecnologias de Informação | G17: Ciências Informáticas | H17: Campus Atlântica, Fábrica da Pólvora de Barcarena, 2730‑036 Barcarena | I17: https://www.google.com/search?q=site%3Auatlantica.pt%20Gest%C3%A3o%20de%20Sistemas%20e%20Tecnologias%20de%20Informa%C3%A7%C3%A3o%20mestrado | J17: 2 ano(s) (120 ECTS) | K17: Presencial | L17: Português | N17: A.M. Lisboa
A18: Atlântica – Instituto Universitário | B18: Portugal | C18: Oeiras | D18: Privada | E18: Mestrado | F18: Segurança e Proteção Civil | G18: Proteção de Pessoas e Bens | H18: Campus Atlântica, Barcarena | I18: https://www.google.com/search?q=site%3Auatlantica.pt%20Seguran%C3%A7a%20e%20Prote%C3%A7%C3%A3o%20Civil%20mestrado | J18: 1,5 ano(s) (90 ECTS) | K18: Presencial | L18: Português | N18: A.M. Lisboa
A19: Atlântica – Instituto Universitário | B19: Portugal | C19: Oeiras | D19: Privada | E19: Pós-Graduação | F19: Curso de Especialista Europeu de Adesivos (EAS) | G19: Ciências Dentárias | H19: Atlântica – Instituto Universitário | I19: https://www.google.com/search?q=site%3Auatlantica.pt%20Curso%20de%20Especialista%20Europeu%20de%20Adesivos%20%28EAS%29%20p%C3%B3s-gradua%C3%A7%C3%A3o | J19: Tempo e créditos não indicados nas páginas de lista consultadas | K19: Presencial | L19: Português | N19: A.M. Lisboa
A20: Atlântica – Instituto Universitário | B20: Portugal | C20: Oeiras | D20: Privada | E20: Pós-Graduação | F20: Pós-Graduação de Fitoterapia Clínica | G20: Ciências Farmacêuticas | H20: Atlântica – Instituto Universitário / área de Saúde | I20: https://www.google.com/search?q=site%3Auatlantica.pt%20P%C3%B3s-Gradua%C3%A7%C3%A3o%20de%20Fitoterapia%20Cl%C3%ADnica%20p%C3%B3s-gradua%C3%A7%C3%A3o | J20: Tempo e créditos não indicados na página de lista consultada | K20: Presencial | L20: Português | N20: A.M. Lisboa
A21: Atlântica – Instituto Universitário | B21: Portugal | C21: Oeiras | D21: Privada | E21: Pós-Graduação | F21: Pós-Graduação em Auditoria Hospitalar e Gestão em Saúde | G21: Contabilidade e Fiscalidade | H21: Atlântica – Instituto Universitário / área de Saúde | I21: https://www.google.com/search?q=site%3Auatlantica.pt%20P%C3%B3s-Gradua%C3%A7%C3%A3o%20em%20Auditoria%20Hospitalar%20e%20Gest%C3%A3o%20em%20Sa%C3%BAde%20p%C3%B3s-gradua%C3%A7%C3%A3o | J21: Tempo e créditos não indicados na página de lista consultada | K21: Presencial | L21: Português | N21: A.M. Lisboa
A22: Atlântica – Instituto Universitário | B22: Portugal | C22: Oeiras | D22: Privada | E22: Pós-Graduação | F22: Pós-Graduação em Data Science (PGDS) | G22: Estatística | H22: Atlântica – Instituto Universitário | I22: https://www.google.com/search?q=site%3Auatlantica.pt%20P%C3%B3s-Gradua%C3%A7%C3%A3o%20em%20Data%20Science%20%28PGDS%29%20p%C3%B3s-gradua%C3%A7%C3%A3o | J22: 13 fevereiro a 13 novembro 2025 (≈9 meses); ECTS não indicados | K22: Online | L22: Português | N22: A.M. Lisboa
A23: Atlântica – Instituto Universitário | B23: Portugal | C23: Oeiras | D23: Privada | E23: Pós-Graduação | F23: Pós-Graduação em Gestão da Qualidade e Segurança em Saúde | G23: Enquadramento na Organização | H23: Atlântica – Instituto Universitário / área de Saúde | I23: https://www.google.com/search?q=site%3Auatlantica.pt%20P%C3%B3s-Gradua%C3%A7%C3%A3o%20em%20Gest%C3%A3o%20da%20Qualidade%20e%20Seguran%C3%A7a%20em%20Sa%C3%BAde%20p%C3%B3s-gradua%C3%A7%C3%A3o | J23: Tempo e créditos não indicados na página de lista consultada | K23: Presencial | L23: Português | N23: A.M. Lisboa
A24: Atlântica – Instituto Universitário | B24: Portugal | C24: Oeiras | D24: Privada | E24: Pós-Graduação | F24: Pós-Graduação em Gestão de Companhias Aéreas | G24: Serviços de Transporte | H24: Atlântica – Instituto Universitário (parceria Aeroclass) | I24: https://www.google.com/search?q=site%3Auatlantica.pt%20P%C3%B3s-Gradua%C3%A7%C3%A3o%20em%20Gest%C3%A3o%20de%20Companhias%20A%C3%A9reas%20p%C3%B3s-gradua%C3%A7%C3%A3o | J24: 0,8 ano(s) (45 ECTS) | K24: Online | L24: Português | N24: A.M. Lisboa
A25: Atlântica – Instituto Universitário | B25: Portugal | C25: Oeiras | D25: Privada | E25: Pós-Graduação | F25: Pós-Graduação em Gestão e Liderança dos Serviços de Saúde | G25: Gestão e Administração | H25: Atlântica – Instituto Universitário / ESSATLA | I25: https://www.google.com/search?q=site%3Auatlantica.pt%20P%C3%B3s-Gradua%C3%A7%C3%A3o%20em%20Gest%C3%A3o%20e%20Lideran%C3%A7a%20dos%20Servi%C3%A7os%20de%20Sa%C3%BAde%20p%C3%B3s-gradua%C3%A7%C3%A3o | J25: Tempo e créditos não indicados na página de lista consultada | K25: Presencial | L25: Português | N25: A.M. Lisboa
A26: Atlântica – Instituto Universitário | B26: Portugal | C26: Oeiras | D26: Privada | E26: Pós-Graduação | F26: Pós-Graduação em Materiais Compósitos | G26: Metalurgia e Metalomecânica | H26: Atlântica – Instituto Universitário | I26: https://www.google.com/search?q=site%3Auatlantica.pt%20P%C3%B3s-Gradua%C3%A7%C3%A3o%20em%20Materiais%20Comp%C3%B3sitos%20p%C3%B3s-gradua%C3%A7%C3%A3o | J26: Tempo e créditos não indicados na página de lista consultada | K26: Presencial | L26: Português | N26: A.M. Lisboa
A27: Atlântica – Instituto Universitário | B27: Portugal | C27: Oeiras | D27: Privada | E27: Pós-Graduação | F27: Pós-Graduação em Novos Modelos de Negócio no Mercado Farmacêutico | G27: Ciências Farmacêuticas | H27: Atlântica – Instituto Universitário / área Farmacêutica | I27: https://www.google.com/search?q=site%3Auatlantica.pt%20P%C3%B3s-Gradua%C3%A7%C3%A3o%20em%20Novos%20Modelos%20de%20Neg%C3%B3cio%20no%20Mercado%20Farmac%C3%AAutico%20p%C3%B3s-gradua%C3%A7%C3%A3o | J27: Tempo e créditos não indicados na página de lista consultada | K27: Presencial | L27: Português | N27: A.M. Lisboa
A28: Atlântica – Instituto Universitário | B28: Portugal | C28: Oeiras | D28: Privada | E28: Pós-Graduação | F28: Pós-Graduação em Sistemas Digitais, Inteligência Artificial e Liderança Tecnológica | G28: Ciências Informáticas | H28: Atlântica – Instituto Universitário (parceria Rumos) | I28: https://www.google.com/search?q=site%3Auatlantica.pt%20P%C3%B3s-Gradua%C3%A7%C3%A3o%20em%20Sistemas%20Digitais%2C%20Intelig%C3%AAncia%20Artificial%20e%20Lideran%C3%A7a%20Tecnol%C3%B3gica%20p%C3%B3s-gradua%C3%A7%C3%A3o | J28: ≈ 6 meses; 135 horas; créditos não indicados | K28: Online | L28: Português | N28: A.M. Lisboa
... A50: Escola Superior Artística do Porto | B50: Portugal | C50: Porto | D50: Privada | E50: Licenciatura | F50: Teatro | G50: Música e Artes do Espetáculo | H50: ESAP, Rua dos Navegantes, 51, 4000‑358 Porto | I50: https://www.google.com/search?q=site%3Aesap.pt%20Teatro%20licenciatura | J50: 3 ano(s) (180 ECTS) | K50: Presencial | L50: Português | N50: Norte
A51: Escola Superior Artística do Porto | B51: Portugal | C51: Porto | D51: Privada | E51: Mestrado | F51: Artes Visuais. Práticas Artísticas e Investigação | G51: Belas‑artes | H51: ESAP, Rua dos Navegantes, 51, 4000‑358 Porto | I51: https://www.google.com/search?q=site%3Aesap.pt%20Artes%20Visuais.%20Pr%C3%A1ticas%20Art%C3%ADsticas%20e%20Investiga%C3%A7%C3%A3o%20mestrado | J51: 2 ano(s) (120 ECTS) | K51: Presencial | L51: Português | M51: Em processo de extinção | N51: Norte
A52: Escola Superior Artística do Porto | B52: Portugal | C52: Porto | D52: Privada | E52: Mestrado | F52: Realização – Cinema e Televisão | G52: Audiovisuais e Produção dos Media | H52: ESAP, Rua dos Navegantes, 51, 4000‑358 Porto | I52: https://www.google.com/search?q=site%3Aesap.pt%20Realiza%C3%A7%C3%A3o%20%E2%80%93%20Cinema%20e%20Televis%C3%A3o%20mestrado | J52: 2 ano(s) (120 ECTS) | K52: Presencial | L52: Português | N52: Norte
A53: Escola Superior Artística do Porto | B53: Portugal | C53: Porto | D53: Privada | E53: Mestrado Integrado | F53: Arquitetura | G53: Arquitetura e Urbanismo | H53: ESAP, Rua dos Navegantes, 51, 4000‑358 Porto | I53: https://www.google.com/search?q=site%3Aesap.pt%20Arquitetura%20mestrado%20integrado | J53: 5 ano(s) (300 ECTS) | K53: Presencial | L53: Português | N53: Norte
A54: Escola Superior Artística do Porto | B54: Portugal | C54: Porto | D54: Privada | E54: Pós-Graduação | F54: Argumento para Cinema e Séries de Ficção | G54: Audiovisuais e Produção dos Media | H54: ESAP – Porto | I54: https://www.google.com/search?q=site%3Aesap.pt%20Argumento%20para%20Cinema%20e%20S%C3%A9ries%20de%20Fic%C3%A7%C3%A3o%20p%C3%B3s-gradua%C3%A7%C3%A3o | J54: Não indicado na página pública consultada (tipicamente 1 ano letivo) | K54: Presencial | L54: Português | N54: Norte
A55: Escola Superior Artística do Porto | B55: Portugal | C55: Porto | D55: Privada | E55: Pós-Graduação | F55: Arquitetura Sustentável | G55: Arquitetura e Urbanismo | H55: ESAP – Porto | I55: https://www.google.com/search?q=site%3Aesap.pt%20Arquitetura%20Sustent%C3%A1vel%20p%C3%B3s-gradua%C3%A7%C3%A3o | J55: Não indicado na página pública consultada (tipicamente 1 ano letivo) | K55: Presencial | L55: Português | N55: Norte
A56: Escola Superior Artística do Porto | B56: Portugal | C56: Porto | D56: Privada | E56: Pós-Graduação | F56: Arte Contemporânea | G56: Belas‑artes | H56: ESAP – Porto | I56: https://www.google.com/search?q=site%3Aesap.pt%20Arte%20Contempor%C3%A2nea%20p%C3%B3s-gradua%C3%A7%C3%A3o | J56: Não indicado na página pública consultada (tipicamente 1 ano letivo) | K56: Presencial | L56: Português | N56: Norte
A57: Escola Superior Artística do Porto | B57: Portugal | C57: Porto | D57: Privada | E57: Pós-Graduação | F57: Arte Sonora e Media Arte | G57: Música e Artes do Espetáculo | H57: ESAP – Porto | I57: https://www.google.com/search?q=site%3Aesap.pt%20Arte%20Sonora%20e%20Media%20Arte%20p%C3%B3s-gradua%C3%A7%C3%A3o | J57: Não indicado na página pública consultada (tipicamente 1 ano letivo) | K57: Presencial | L57: Português | N57: Norte
A58: Escola Superior Artística do Porto | B58: Portugal | C58: Porto | D58: Privada | E58: Pós-Graduação | F58: Artes Digitais e Novos Media | G58: Audiovisuais e Produção dos Media | H58: ESAP – Porto | I58: https://www.google.com/search?q=site%3Aesap.pt%20Artes%20Digitais%20e%20Novos%20Media%20p%C3%B3s-gradua%C3%A7%C3%A3o | J58: 1 ano letivo; créditos definidos por regulamento próprio (indicada como especialização/pós‑graduação) | K58: Presencial | L58: Português | N58: Norte
A59: Escola Superior Artística do Porto | B59: Portugal | C59: Porto | D59: Privada | E59: Pós-Graduação | F59: Artes Visuais e Investigação | G59: Belas‑artes | H59: ESAP – Porto | I59: https://www.google.com/search?q=site%3Aesap.pt%20Artes%20Visuais%20e%20Investiga%C3%A7%C3%A3o%20p%C3%B3s-gradua%C3%A7%C3%A3o | J59: Não indicado na página pública consultada (tipicamente 1 ano letivo) | K59: Presencial | L59: Português | N59: Norte
A60: Escola Superior Artística do Porto | B60: Portugal | C60: Porto | D60: Privada | E60: Pós-Graduação | F60: Auto‑edição | G60: Línguas e Literaturas | H60: ESAP – Porto | I60: https://www.google.com/search?q=site%3Aesap.pt%20Auto%E2%80%91edi%C3%A7%C3%A3o%20p%C3%B3s-gradua%C3%A7%C3%A3o | J60: Não indicado na página pública consultada (tipicamente 1 ano letivo) | K60: Presencial | L60: Português | N60: Norte
A61: Escola Superior Artística do Porto | B61: Portugal | C61: Porto | D61: Privada | E61: Pós-Graduação | F61: Banda Desenhada | G61: Design | H61: ESAP – Porto | I61: https://www.google.com/search?q=site%3Aesap.pt%20Banda%20Desenhada%20p%C3%B3s-gradua%C3%A7%C3%A3o | J61: Não indicado na página pública consultada (tipicamente 1 ano letivo) | K61: Presencial | L61: Português | N61: Norte
...

Sheet Análise
A1: ANÁLISE — Oferta Formativa de Portugal (tabelas e gráficos por fórmulas COUNTIF)
A3: 1) Cursos por Tipologia
A4: Categoria | B4: Nº cursos
A5: Mestrado | B5: =COUNTIF('Oferta Formativa PT'!E:E,"Mestrado") -> 2126
A6: Licenciatura | B6: =COUNTIF('Oferta Formativa PT'!E:E,"Licenciatura") -> 1498
A7: Pós-Graduação | B7: =COUNTIF('Oferta Formativa PT'!E:E,"Pós-Graduação") -> 1139
A8: Curso Técnico Superior Profissional (CTeSP) | B8: =COUNTIF('Oferta Formativa PT'!E:E,"Curso Técnico Superior Profissional (CTeSP)") -> 893
A9: Mestrado Integrado | B9: =COUNTIF('Oferta Formativa PT'!E:E,"Mestrado Integrado") -> 103
A10: Pós-Graduação Executiva | B10: =COUNTIF('Oferta Formativa PT'!E:E,"Pós-Graduação Executiva") -> 45
A12: 2) Cursos por Modalidade
A13: Categoria | B13: Nº cursos
A14: Presencial | B14: =COUNTIF('Oferta Formativa PT'!K:K,"Presencial") -> 5336
A15: Híbrido / B-learning | B15: =COUNTIF('Oferta Formativa PT'!K:K,"*brido*")+COUNTIF('Oferta Formativa PT'!K:K,"*emipres*") -> 269
A16: Online / A distância | B16: =COUNTIF('Oferta Formativa PT'!K:K,"*nline*")+COUNTIF('Oferta Formativa PT'!K:K,"*dist*") -> 199
A18: 3) Pública vs Privada
A19: Categoria | B19: Nº cursos
A20: Pública | B20: =COUNTIF('Oferta Formativa PT'!D:D,"Pública") -> 4133
A21: Privada | B21: =COUNTIF('Oferta Formativa PT'!D:D,"Privada") -> 1671
A23: 4) Estado
A24: Categoria | B24: Nº cursos
A25: Em funcionamento (ativo) | B25: =COUNTA('Oferta Formativa PT'!A:A)-1-COUNTIF('Oferta Formativa PT'!M:M,"*extin*") -> 5533
A26: Em processo de extinção | B26: =COUNTIF('Oferta Formativa PT'!M:M,"*extin*") -> 271
A28: 5) Cursos por Região
A29: Categoria | B29: Nº cursos
A30: A.M. Lisboa | B30: =COUNTIF('Oferta Formativa PT'!N:N,"A.M. Lisboa") -> 1921
A31: Norte | B31: =COUNTIF('Oferta Formativa PT'!N:N,"Norte") -> 1788
A32: Centro | B32: =COUNTIF('Oferta Formativa PT'!N:N,"Centro") -> 1203
A33: Outras/Múltiplas | B33: =COUNTIF('Oferta Formativa PT'!N:N,"Outras/Múltiplas") -> 411
A34: Alentejo | B34: =COUNTIF('Oferta Formativa PT'!N:N,"Alentejo") -> 244
A35: Algarve | B35: =COUNTIF('Oferta Formativa PT'!N:N,"Algarve") -> 162
A36: Açores | B36: =COUNTIF('Oferta Formativa PT'!N:N,"Açores") -> 58
A37: Madeira | B37: =COUNTIF('Oferta Formativa PT'!N:N,"Madeira") -> 17
A39: 6) Áreas Científicas (Top)
A40: Categoria | B40: Nº cursos
A41: Gestão e Administração | B41: =COUNTIF('Oferta Formativa PT'!G:G,"Gestão e Administração") -> 510
A42: Ciências Informáticas | B42: =COUNTIF('Oferta Formativa PT'!G:G,"Ciências Informáticas") -> 376
A43: Enfermagem | B43: =COUNTIF('Oferta Formativa PT'!G:G,"Enfermagem") -> 261
A44: Ciências da Educação | B44: =COUNTIF('Oferta Formativa PT'!G:G,"Ciências da Educação") -> 211
A45: Biologia e Bioquímica | B45: =COUNTIF('Oferta Formativa PT'!G:G,"Biologia e Bioquímica") -> 186
A46: Marketing e Publicidade | B46: =COUNTIF('Oferta Formativa PT'!G:G,"Marketing e Publicidade") -> 178
...

Sheet Relatório
A1: RELATÓRIO DA FASE 3
A2: Oferta Formativa do Ensino Superior — Portugal. Levantamento, estruturação, validação e análise da oferta formativa, com base em fontes oficiais. Documento ao serviço da leitura e utilização estratégica desta informação pelo Instituto Piaget.
A4: ════════ I · CONCLUSÕES E RESPOSTA À PROPOSTA FINAL ════════
A5: Pergunta do enunciado:
A6: « Que tendências, concentrações de oferta ou padrões relevantes foram identificados na oferta formativa de Portugal e Espanha, e que utilidade estratégica poderá essa informação ter para análise futura? »
A7: A minha resposta (breve, objetiva e baseada apenas na informação recolhida):
A8: 1) A oferta concentra-se no 2.º ciclo. A tipologia dominante é «Mestrado» (2126 cursos, 37% do total). Somando Mestrado, Mestrado Integrado e as duas Pós-Graduações, o segmento pós-graduado é o maior bloco do mercado português.
A9: 2) Há forte concentração geográfica: a oferta acumula-se na A.M. Lisboa (1921 cursos), no Norte (1788) e no Centro (1203) — estas três regiões concentram a esmagadora maioria da oferta nacional; Alentejo, Algarve, Açores e Madeira têm volumes residuais.
A10: 3) As áreas com mais oferta — e, logo, mais concorrência — são Gestão e Administração (510), Ciências Informáticas (376) e Enfermagem (261), seguidas de Ciências da Educação, Biologia/Bioquímica e Marketing e Publicidade.
A11: 4) Portugal aposta fortemente na formação curta e profissionalizante: o CTeSP (nível 5, 893 cursos) e as Pós-Graduações (1139 + 45 Executivas) somam mais de um terço da oferta — um segmento orientado à empregabilidade e de captação mais rápida.
A12: 5) Predomina o ensino público em volume (4133 cursos públicos vs 1671 privados), mas as instituições privadas e o ensino online/híbrido têm presença relevante, sobretudo na pós-graduação.
A13: Utilidade estratégica para o Instituto Piaget: esta base permite (i) ver onde a concorrência é mais densa, por área e por região, e onde há espaço de oferta; (ii) priorizar prospeção e posicionamento, com destaque para a formação curta (CTeSP e pós-graduação), o segmento mais sensível a marketing de captação; (iii) monitorizar a oferta ativa face à que está em extinção, para antecipar movimentos do mercado.
... A68: Rigor da informação (dados de fontes oficiais, 0 lacunas por inferência, duplicados removidos); uso de fontes oficiais (DGES/A3ES + sites institucionais); organização estruturada (13 colunas + região, sem redundâncias); coerência na classificação (tipologias e áreas uniformizadas); facilidade de leitura e filtragem (AutoFilter por instituição, tipologia, área e região); utilidade prática (KPIs e 6 gráficos na folha «Análise»).
